Workbook

Sheet ROE
A1: Ticker | B1: Sector | C1: 44286 | D1: 44377 | E1: 44469 | F1: 44561 | G1: 44651 | H1: 44742 | I1: 44834 | J1: 44926 | K1: 45016 | L1: 45107 | M1: 45199 | N1: 45291 | O1: 45382 | P1: 45473 | Q1: 45565 | R1: 45657 | S1: 45747 | T1: 45838 | U1: 45930 | V1: 46022 | W1: 46097 | X1: Latest ROE
A2: A UN Equity | B2: Health Care | C2: 16.7841 | D2: 19.3151 | E2: 19.9456 | F2: 23.5821 | G2: 24.2016 | H2: 25.4329 | I2: 26.4621 | J2: 23.4524 | K2: 24.5842 | L2: 24.7822 | M2: 21.279 | N2: 22.2422 | O2: 20.9545 | P2: 20.7086 | Q2: 24.6575 | R2: 21.9535 | S2: 20.614 | T2: 18.8826 | U2: 19.881 | V2: 20.6187 | W2: 19.9459 | X2: 19.9459
A3: AAPL UW Equity | B3: Information Technology | C3: 103.4003 | D3: 127.1247 | E3: 147.4433 | F3: 145.5673 | G3: 149.2711 | H3: 162.8163 | I3: 175.4593 | J3: 147.943 | K3: #N/A N/A | L3: 145.6054 | M3: 171.9495 | N3: 154.2694 | O3: 147.2498 | P3: 160.5834 | Q3: 157.4125 | R3: 136.5205 | S3: 138.0155 | T3: 149.8136 | U3: 171.4224 | V3: 152.0213 | W3: #N/A N/A | X3: #N/A N/A | AC3: 22.2422 | AD3: 16.7841
A4: ABBV UN Equity | B4: Health Care | C4: #N/A N/A | D4: 48.3484 | E4: 51.7765 | F4: 80.4592 | G4: 80.4592 | H4: 92.3738 | I4: 90.3466 | J4: 72.1634 | K4: 72.1634 | L4: 62.7494 | M4: 46.0695 | N4: 34.9026 | O4: 55.9184 | P4: 53.93 | Q4: 56.1735 | R4: 62.0826 | S4: 62.0826 | T4: #N/A N/A | U4: #N/A N/A | V4: #N/A N/A | W4: #N/A N/A | X4: #N/A N/A | AD4: 16.7841
A5: ABNB UW Equity | B5: Consumer Discretionary | C5: #N/A N/A | D5: #N/A N/A | E5: #N/A N/A | F5: -9.1584 | G5: 82.6726 | H5: 28.9166 | I5: 32.6224 | J5: 36.6393 | K5: 51.0539 | L5: 44.6483 | M5: 74.4725 | N5: 69.8288 | O5: 74.9071 | P5: 74.175 | Q5: 20.8733 | R5: 31.9479 | S5: 88.5754 | T5: 33.2615 | U5: 30.7755 | V5: 30.233 | W5: 30.233 | X5: 30.233 | AA5: 24.6575 | AB5: 45295 | AC5: 131
A6: ABT UN Equity | B6: Health Care | C6: 14.075 | D6: 19.808 | E6: 22.0156 | F6: 20.6194 | G6: 20.309 | H6: 24.3392 | I6: 22.5088 | J6: 19.1287 | K6: 40.4676 | L6: 14.0123 | M6: 14.1123 | N6: 15.2028 | O6: 14.851 | P6: 14.5296 | Q6: 14.9255 | R6: 31.071 | S6: 32.0596 | T6: 31.1049 | U6: 30.8033 | V6: 13.0749 | W6: 13.0749 | X6: 13.0749 | Y6: 45294 | Z6: 184.25 | AA6: 21.9535 | AB6: 45296 | AC6: 130.56
A7: AAL UW Equity | B7: Industrials | C7: 17.9492 | D7: #N/A N/A | E7: #N/A N/A | F7: #N/A N/A | G7: 22.404 | H7: #N/A N/A | I7: #N/A N/A | J7: #N/A N/A | K7: 16.0312 | L7: #N/A N/A | M7: #N/A N/A | N7: #N/A N/A | O7: #N/A N/A | P7: #N/A N/A | Q7: #N/A N/A | R7: #N/A N/A | S7: 30.8191 | T7: #N/A N/A | U7: #N/A N/A | V7: #N/A N/A | W7: #N/A N/A | X7: #N/A N/A | Y7: 45295 | Z7: 181.91 | AA7: 45299 | AB7: 45299 | AC7: 133.38
A8: ACGL UW Equity | B8: Financials | C8: 11.2953 | D8: 17.0027 | E8: 16.25 | F8: 16.3578 | G8: 16.3578 | H8: 13.0239 | I8: 10.205 | J8: 11.5879 | K8: 11.5879 | L8: 17.501 | M8: 23.0826 | N8: 29.7469 | O8: 30.3487 | P8: 32.1346 | Q8: 31.6347 | R8: 22.7761 | S8: 22.7761 | T8: 17.5712 | U8: 18.2979 | V8: 20.1033 | W8: 20.1033 | X8: 20.1033 | Y8: 45296 | Z8: 181.18 | AA8: 45300 | AB8: 45300 | AC8: 130.68
A9: AAP UN Equity | B9: Consumer Discretionary | C9: 14.1371 | D9: 18.0537 | E9: 17.7601 | F9: 18.5779 | G9: 15.1737 | H9: 17.7803 | I9: 17.5736 | J9: 16.2955 | K9: 15.4919 | L9: 14.119 | M9: 11.8045 | N9: 5.5107 | O9: #N/A N/A | P9: 0.8234 | Q9: -0.4565 | R9: 1.6731 | S9: 18.9899 | T9: -14.7754 | U9: -15.8751 | V9: -15.723 | W9: 2.0147 | X9: 2.0147 | Y9: 45299 | Z9: 185.56 | AA9: 45301 | AB9: 45301 | AC9: 131.09
A10: ACN UN Equity | B10: Information Technology | C10: 32.3081 | D10: 32.6861 | E10: 32.3395 | F10: 32.3973 | G10: 32.8889 | H10: 32.5459 | I10: 33.0351 | J10: 16.8653 | K10: 31.3149 | L10: 30.6656 | M10: 28.7519 | N10: 1.1618 | O10: 27.6356 | P10: 26.2014 | Q10: 26.9158 | R10: -14.3199 | S10: 27.2613 | T10: 27.2689 | U10: 25.8168 | V10: 25.3458 | W10: #N/A N/A | X10: #N/A N/A | Y10: 45300 | Z10: 185.14 | AA10: 45302 | AB10: 45302 | AC10: 129.68
A11: ADBE UW Equity | B11: Information Technology | C11: 46.3621 | D11: 45.1381 | E11: 44.6971 | F11: 34.368 | G11: 35.3355 | H11: 35.1259 | I11: 33.4387 | J11: 32.9728 | K11: 33.8587 | L11: 33.6814 | M11: 33.9713 | N11: 35.5131 | O11: 32.367 | P11: 34.2239 | Q11: 35.355 | R11: 36.3126 | S11: 47.2842 | T11: 52.2536 | U11: 52.8748 | V11: 55.426 | W11: 58.7736 | X11: 58.7736 | Y11: 45301 | Z11: 186.19 | AA11: 45303 | AB11: 45303 | AC11: 130.54
A12: ADI UW Equity | B12: Information Technology | C12: 11.8214 | D12: 13.1376 | E12: 14.1527 | F12: 5.5627 | G12: 5.1781 | H12: 6.6671 | I12: 7.7216 | J12: 7.3829 | K12: 9.2753 | L12: 9.9144 | M12: 10.3453 | N12: 9.2033 | O12: 7.8131 | P12: 6.0072 | Q12: 4.6576 | R12: 4.6232 | S12: 4.429 | T12: 5.2132 | U12: 5.6518 | V12: 6.5728 | W12: 7.8622 | X12: 7.8622 | Y12: 45302 | Z12: 185.59 | AA12: 45307 | AB12: 45307 | AC12: 130.53
A13: ADM UN Equity | B13: Consumer Staples | C13: 9.039 | D13: 11.3174 | E13: 12.6614 | F13: 12.7551 | G13: 12.7551 | H13: 15.652 | I13: 17.8523 | J13: 18.5625 | K13: 18.5625 | L13: 16.8126 | M13: 15.9959 | N13: 14.3878 | O13: 12.6542 | P13: 11.0476 | Q13: 7.6183 | R13: 7.7754 | S13: 7.7754 | T13: 4.9307 | U13: 5.3479 | V13: 4.8017 | W13: 4.8017 | X13: 4.8017 | Y13: 45303 | Z13: 185.92 | AA13: 45308 | AB13: 45308 | AC13: 128.12
A14: ADP UW Equity | B14: Industrials | C14: 10.4038 | D14: 45.4987 | E14: 48.3333 | F14: 50.1169 | G14: 13.7962 | H14: 66.2994 | I14: 76.3775 | J14: 78.2947 | K14: 18.3442 | L14: 101.3275 | M14: 115.4613 | N14: 97.3844 | O14: 88.9225 | P14: 93.1399 | Q14: 87.2628 | R14: 83.7162 | S14: 6.0259 | T14: 76.0013 | U14: 70.5709 | V14: 73.8395 | W14: 73.8395 | X14: 73.8395 | Y14: 45307 | Z14: 183.63 | AA14: 45309 | AB14: 45309 | AC14: 130.46
A15: ADSK UW Equity | B15: Information Technology | C15: 44.2792 | D15: #N/A N/A | E15: 188.5313 | F15: 195.6567 | G15: 58.0046 | H15: 53.9074 | I15: 53.9801 | J15: 56.6449 | K15: 82.686 | L15: 106.2104 | M15: 89.8253 | N15: 76.8007 | O15: 60.4 | P15: 65.206 | Q15: 57.4457 | R15: 53.2455 | S15: 76.2889 | T15: 42.3608 | U15: 40.2004 | V15: 40.334 | W15: 39.6753 | X15: 39.6753 | Y15: 45308 | Z15: 182.68 | AA15: 45310 | AB15: 45310 | AC15: 131.22
A16: AEE UN Equity | B16: Utilities | C16: 10.2489 | D16: #N/A N/A | E16: #N/A N/A | F16: #N/A N/A | G16: #N/A N/A | H16: 10.4924 | I16: 10.4194 | J16: 10.6295 | K16: 10.6295 | L16: 10.8471 | M16: 10.8925 | N16: 10.5412 | O16: 10.4218 | P16: 10.5235 | Q16: 9.9056 | R16: 10.0754 | S16: 10.0754 | T16: 10.288 | U16: 11.4655 | V16: 11.4129 | W16: 11.4129 | X16: 11.4129 | Y16: 45309 | Z16: 188.63 | AA16: 45313 | AB16: 45313 | AC16: 132.55
A17: AEP UW Equity | B17: Utilities | C17: 11.1182 | D17: 11.2586 | E17: 11.1461 | F17: 11.5531 | G17: 11.5531 | H17: 11.299 | I17: 10.5424 | J17: 9.9414 | K17: 10.6403 | L17: 8.2611 | M17: 9.0726 | N17: 6.2594 | O17: 8.6478 | P17: 7.8388 | Q17: 7.5739 | R17: 11.3518 | S17: 10.2274 | T17: 12.77 | U17: 12.8195 | V17: #N/A N/A | W17: #N/A N/A | X17: #N/A N/A | Y17: 45310 | Z17: 191.56 | AA17: 45314 | AB17: 45314 | AC17: 131.64
A18: AES UN Equity | B18: Utilities | C18: 11.1733 | D18: -5.7643 | E18: 24.3529 | F18: -17.7556 | G18: 11.7118 | H18: -16.1224 | I18: -10.978 | J18: -30.5711 | K18: 8.352 | L18: -19.4175 | M18: -24.8227 | N18: 15.3278 | O18: 23.9602 | P18: 35.8693 | Q18: 42.9746 | R18: 67.1704 | S18: 10.3874 | T18: 31.1146 | U18: 31.7261 | V18: 23.3554 | W18: 23.3554 | X18: 23.3554 | Y18: 45313 | Z18: 193.89 | AA18: 45315 | AB18: 45315 | AC18: 129.78
A19: AFL UN Equity | B19: Financials | C19: -10.0964 | D19: 18.3833 | E19: 12.8334 | F19: 12.9468 | G19: -6.4317 | H19: 14.5305 | I19: 18.2344 | J19: 16.549 | K19: -27.3458 | L19: 20.4972 | M19: 19.5938 | N19: 22.1199 | O19: 24.6993 | P19: 23.5383 | Q19: 16.0382 | R19: 22.64 | S19: 43.7186 | T19: 9.1536 | U19: 15.5798 | V19: 13.1179 | W19: 13.1179 | X19: 13.1179 | Y19: 45314 | Z19: 195.18 | AA19: 45316 | AB19: 45316 | AC19: 129.88
A20: AIG UN Equity | B20: Financials | C20: 18.8189 | D20: 6.5679 | E20: 8.6895 | F20: 14.2539 | G20: 13.2371 | H20: 22.8078 | I20: 26.3547 | J20: 19.7874 | K20: 18.4908 | L20: 11.0463 | M20: 10.3258 | N20: 8.4715 | O20: 11.1666 | P20: -1.5671 | Q20: -5.2956 | R20: -3.283 | S20: 14.408 | T20: 7.4442 | U20: 7.5682 | V20: 7.4459 | W20: 7.4459 | X20: 7.4459 | Y20: 45315 | Z20: 194.5 | AA20: 45317 | AB20: 45317 | AC20: 130.99
A21: AIZ UN Equity | B21: Financials | C21: -6.3126 | D21: 8.0044 | E21: 24.2476 | F21: #N/A N/A | G21: 16.3473 | H21: 23.2868 | I21: 6.7477 | J21: 5.7073 | K21: 12.8313 | L21: 7.7199 | M21: 12.2964 | N21: 14.2174 | O21: 16.4291 | P21: 16.8108 | Q21: 15.2146 | R21: 15.3325 | S21: -4.559 | T21: 13.6535 | U21: 15.4134 | V21: 15.8986 | W21: 15.8986 | X21: 15.8986 | Y21: 45316 | Z21: 194.17 | AA21: 45320 | AB21: 45320 | AC21: 132.83
A22: AJG UN Equity | B22: Financials | C22: 7.914 | D22: 12.9133 | E22: 13.2414 | F22: 12.3419 | G22: 12.3419 | H22: 12.3518 | I22: 12.8057 | J22: 12.6241 | K22: 5.1224 | L22: 11.5838 | M22: 11.9471 | N22: 9.7345 | O22: 10.3359 | P22: 10.3814 | Q22: 10.3517 | R22: 9.4585 | S22: 13.2044 | T22: 9.4873 | U22: 9.0489 | V22: 6.8725 | W22: 6.8725 | X22: 6.8725 | Y22: 45317 | Z22: 192.42 | AA22: 45321 | AB22: 45321 | AC22: 134.28
A23: AKAM UW Equity | B23: Information Technology | C23: 14.5333 | D23: 13.9408 | E23: 13.9119 | F23: 14.8416 | G23: 12.2566 | H23: 13.5287 | I23: 12.1861 | J23: 11.3691 | K23: 12.357 | L23: 11.1645 | M23: 12.0417 | N23: 12.2275 | O23: 14.2177 | P23: 13.9059 | Q23: 11.5411 | R23: 10.6573 | S23: 9.2722 | T23: 9.2083 | U23: 10.6416 | V23: 9.173 | W23: 9.173 | X23: 9.173 | Y23: 45320 | Z23: 191.73 | AA23: 45322 | AB23: 45322 | AC23: 130.1
A24: ALB UN Equity | B24: Materials | C24: 14.7519 | D24: 13.802 | E24: 4.3208 | F24: 2.5001 | G24: 14.5983 | H24: 4.3026 | I24: 25.0033 | J24: 39.5332 | K24: 11.0743 | L24: 49.2847 | M24: 39.9701 | N24: 18.0913 | O24: 3.5198 | P24: -5.915 | Q24: -22.0578 | R24: -15.4166 | S24: 9.8211 | T24: -13.0012 | U24: -2.3935 | V24: -9.0954 | W24: -9.0954 | X24: -9.0954 | Y24: 45321 | Z24: 188.04 | AA24: 45323 | AB24: 45323 | AC24: 133.05
A25: ALGN UW Equity | B25: Health Care | C25: 7.569 | D25: 22.4241 | E25: 22.5961 | F25: 22.5191 | G25: 4.8627 | H25: 17.7283 | I25: 14.1654 | J25: 10.0102 | K25: 48.872 | L25: 8.6796 | M25: 9.6796 | N25: 12.3081 | O25: 12.7704 | P25: 12.0882 | Q25: 11.4009 | R25: 11.2626 | S25: -15.2985 | T25: 11.4099 | U25: 9.5775 | V25: 10.3871 | W25: 10.3871 | X25: 10.3871 | Y25: 45322 | Z25: 184.4 | AA25: 45324 | AB25: 45324 | AC25: 132.97
A26: ALL UN Equity | B26: Financials | C26: 14.6683 | D26: 14.7033 | E26: 12.4872 | F26: 5.7843 | G26: 19.9971 | H26: 3.8546 | I26: -1.5365 | J26: -7.2662 | K26: 8.8171 | L26: -17.3147 | M26: -14.7494 | N26: -2.0267 | O26: 7.605 | P26: 19.3869 | Q26: 26.2098 | R26: 25.9171 | S26: 10.8435 | T26: 29.6271 | U26: 37.3109 | V26: 42.3966 | W26: 42.3966 | X26: 42.3966 | Y26: 45323 | Z26: 186.86 | AA26: 45327 | AB26: 45327 | AC26: 132.82
A27: ALLE UN Equity | B27: Industrials | C27: 15.1762 | D27: 63.8933 | E27: 54.9008 | F27: 60.7995 | G27: 15.4385 | H27: 59.4913 | I27: 52.6004 | J27: 53.8538 | K27: -13.002 | L27: 53.8136 | M27: 55.0657 | N27: 47.8209 | O27: 45.1977 | P27: 43.2232 | Q27: 40.812 | R27: 42.3909 | S27: 21.4625 | T27: 38.9937 | U27: 36.4112 | V27: 36.0844 | W27: 36.0844 | X27: 36.0844 | Y27: 45324 | Z27: 185.85 | AA27: 45328 | AB27: 45328 | AC27: 135.86
A28: AMAT UW Equity | B28: Information Technology | C28: 63.0172 | D28: 42.1754 | E28: 49.073 | F28: 51.5926 | G28: 63.6902 | H28: 57.3222 | I28: 55.085 | J28: 53.3939 | K28: 54.7861 | L28: 50.4823 | M28: 47.4395 | N28: 48.0398 | O28: 46.4067 | P28: 45.193 | Q28: 43.9101 | R28: 40.6054 | S28: 42.0515 | T28: 36.3724 | U28: 35.6353 | V28: 35.5084 | W28: 38.8627 | X28: 38.8627 | Y28: 45327 | Z28: 187.68 | AA28: 45329 | AB28: 45329 | AC28: 132.79
A29: AMCR UN Equity | B29: Materials | C29: 15.34 | D29: 20.0002 | E29: 20.1992 | F29: 20.51 | G29: 20.51 | H29: 18.2003 | I29: 19.4911 | J29: 24.2541 | K29: 24.2541 | L29: 25.8757 | M29: 24.7953 | N29: 15.4864 | O29: 15.9668 | P29: 18.4647 | Q29: 19.6751 | R29: 20.5989 | S29: 20.5989 | T29: 6.5475 | U29: 7.4439 | V29: 7.7302 | W29: 7.7302 | X29: 7.7302 | Y29: 45328 | Z29: 189.3 | AA29: 45330 | AB29: 45330 | AC29: 134.07
A30: AMD UW Equity | B30: Information Technology | C30: 18.39 | D30: 66.2681 | E30: 72.144 | F30: 47.4276 | G30: 20.7551 | H30: 10.0588 | I30: 7.3705 | J30: 4.2412 | K30: 22.2932 | L30: 0.718 | M30: 0.3799 | N30: 1.5437 | O30: 2.0128 | P30: 2.4249 | Q30: 3.262 | R30: 2.8926 | S30: 20.7056 | T30: 4.8777 | U30: 5.6141 | V30: 7.191 | W30: #N/A N/A | X30: #N/A N/A | Y30: 45329 | Z30: 189.41 | AA30: 45331 | AB30: 45331 | AC30: 133.34
A31: ALK UN Equity | B31: Industrials | C31: -36.1798 | D31: -17.0355 | E31: 0.3722 | F31: 14.0816 | G31: 14.0816 | H31: 5.8402 | I31: 1.468 | J31: 1.5229 | K31: 1.5229 | L31: 4.129 | M31: 6.5412 | N31: 5.9276 | O31: 6.3919 | P31: 5.5032 | Q31: 7.5128 | R31: 9.3105 | S31: 9.3105 | T31: 7.6641 | U31: 3.5261 | V31: 2.3557 | W31: 2.3557 | X31: 2.3557 | Y31: 45330 | Z31: 188.32 | AA31: 45334 | AB31: 45334 | AC31: 132.31
A32: AME UN Equity | B32: Industrials | C32: -35.5007 | D32: 14.8189 | E32: 15.1583 | F32: 15.444 | G32: 14.312 | H32: 16.4587 | I32: 16.5676 | J32: 16.1627 | K32: 1.6107 | L32: 16.4279 | M32: 16.5091 | N32: 16.2055 | O32: 15.7655 | P32: 15.3672 | Q32: 14.8857 | R32: 14.9697 | S32: 8.8982 | T32: 14.6389 | U32: 14.6316 | V32: 14.5941 | W32: 14.5941 | X32: 14.5941 | Y32: 45331 | Z32: 188.85 | AA32: 45335 | AB32: 45335 | AC32: 129.76
A33: AMGN UW Equity | B33: Health Care | C33: 14.1709 | D33: 60.7849 | E33: 58.5002 | F33: 73.1641 | G33: 15.9858 | H33: 123.3077 | I33: 115.1643 | J33: 126.4743 | K33: 16.241 | L33: 173.4565 | M33: 133.8049 | N33: 135.793 | O33: 72.5747 | P33: 49.2681 | Q33: 55.7202 | R33: 67.5531 | S33: 14.9638 | T33: 99.1388 | U33: 81.71 | V33: 106.1025 | W33: 106.1025 | X33: 106.1025 | Y33: 45334 | Z33: 187.15 | AA33: 45336 | AB33: 45336 | AC33: 132.24
A34: AMP UN Equity | B34: Financials | C34: 75.2962 | D34: 17.4791 | E34: 37.982 | F34: 47.7839 | G34: 111.6683 | H34: 62.2022 | I34: 69.9911 | J34: 61.7622 | K34: 252.7778 | L34: 68.2729 | M34: 75.4872 | N34: 59.9156 | O34: 69.3561 | P34: 67.6292 | Q34: 56.7505 | R34: 68.3137 | S34: 105.6728 | T34: 58.2393 | U34: 59.5892 | V34: 60.5078 | W34: 60.5078 | X34: 60.5078 | Y34: 45335 | Z34: 185.04 | AA34: 45337 | AB34: 45337 | AC34: 134.75
A35: AMT UN Equity | B35: Real Estate | C35: -1.066 | D35: 47.3796 | E35: 54.2366 | F35: 55.9735 | G35: 58.6758 | H35: 43.8342 | I35: 49.6536 | J35: 33.1494 | K35: 56.4999 | L35: 15.957 | M35: 13.2149 | N35: 30.3625 | O35: 43.6812 | P35: 55.1849 | Q35: 27.1633 | R35: 59.4955 | S35: 58.1077 | T35: 34.1613 | U35: 77.3833 | V35: 71.9149 | W35: 71.9149 | X35: 71.9149 | Y35: 45336 | Z35: 184.15 | AA35: 45338 | AB35: 45338 | AC35: 134.84
A36: AMZN UW Equity | B36: Consumer Discretionary | C36: 51.0947 | D36: 31.2288 | E36: 25.8317 | F36: 28.8056 | G36: 56.9822 | H36: 9.4287 | I36: 8.7757 | J36: -1.915 | K36: 25.8115 | L36: 8.7146 | M36: 12.5313 | N36: 17.4898 | O36: 20.3046 | P36: 21.9327 | Q36: 22.5584 | R36: 24.2897 | S36: 48.1708 | T36: 24.7704 | U36: 24.327 | V36: 22.2858 | W36: 22.2858 | X36: 22.2858 | Y36: 45337 | Z36: 183.86 | AA36: 45342 | AB36: 45342 | AC36: 134.14
A37: ANET UN Equity | B37: Information Technology | C37: 31.9149 | D37: 21.638 | E37: 22.5788 | F37: 23.0406 | G37: 18.0456 | H37: 26.8693 | I37: 28.2324 | J37: 30.514 | K37: 2.9765 | L37: 34.6625 | M37: 34.9061 | N37: 34.4873 | O37: 34.6972 | P37: 34.4627 | Q37: 33.8343 | R37: 33.1367 | S37: 25.2404 | T37: 33.6382 | U37: 31.7364 | V37: 31.4004 | W37: 31.4004 | X37: 31.4004 | Y37: 45338 | Z37: 182.31 | AA37: 45343 | AB37: 45343 | AC37: 135.33
A38: ANSS UW Equity | B38: Information Technology | C38: 21.4754 | D38: 11.8979 | E38: 11.782 | F38: 10.595 | G38: 24.5314 | H38: 10.5321 | I38: 10.5581 | J38: 11.2025 | K38: 31.9891 | L38: 11.1895 | M38: 10.1272 | N38: 9.7582 | O38: 8.5278 | P38: 9.4292 | Q38: 10.4797 | R38: 10.0323 | S38: 33.681 | T38: #N/A N/A | U38: #N/A N/A | V38: #N/A N/A | W38: #N/A N/A | X38: #N/A N/A | Y38: 45342 | Z38: 181.56 | AA38: 45344 | AB38: 45344 | AC38: 132.02
A39: AON UN Equity | B39: Financials | C39: 12.4311 | D39: 51.8914 | E39: 31.8901 | F39: 55.0922 | G39: 10.6942 | H39: 57.7925 | I39: #N/A N/A | J39: #N/A N/A | K39: 12.1001 | L39: 714.2857 | M39: #N/A N/A | N39: #N/A N/A | O39: #N/A N/A | P39: 86.0422 | Q39: #N/A N/A | R39: #N/A N/A | S39: 10.2299 | T39: 37.9917 | U39: 38.3276 | V39: 47.7606 | W39: 47.7606 | X39: 47.7606 | Y39: 45343 | Z39: 182.32 | AA39: 45345 | AB39: 45345 | AC39: 132.03
A40: AOS UN Equity | B40: Industrials | C40: 56.8313 | D40: 25.4029 | E40: 25.6614 | F40: 26.4692 | G40: 50.2115 | H40: 28.6633 | I40: 27.1877 | J40: 13.168 | K40: 13.168 | L40: 14.8659 | M40: 16.4839 | N40: 30.9902 | O40: 31.4434 | P40: 30.3421 | Q40: 29.5438 | R40: 28.6274 | S40: 28.6274 | T40: 27.6035 | U40: 28.2091 | V40: 29.1968 | W40: 29.1968 | X40: 29.1968 | Y40: 45344 | Z40: 184.37 | AA40: 45348 | AB40: 45348 | AC40: 131.49
...

Sheet EPS
A1: Ticker | B1: Sector | C1: 44286 | D1: 44377 | E1: 44469 | F1: 44561 | G1: 44651 | H1: 44742 | I1: 44834 | J1: 44926 | K1: 45016 | L1: 45107 | M1: 45199 | N1: 45291 | O1: 45382 | P1: 45473 | Q1: 45565 | R1: 45657 | S1: 45747 | T1: 45838 | U1: 45930 | V1: 46022 | W1: 46112 | X1: Latest ROE
A2: 2499073D UN Equity | B2: Industrials | C2: 6.2718 | D2: 7.3108 | E2: 7.0933 | F2: 13.3949 | G2: #N/A N/A | H2: #N/A N/A | I2: #N/A N/A | J2: #N/A N/A | K2: #N/A N/A | L2: #N/A N/A | M2: #N/A N/A | N2: #N/A N/A | O2: #N/A N/A | P2: #N/A N/A | Q2: #N/A N/A | R2: #N/A N/A | S2: #N/A N/A | T2: #N/A N/A | U2: #N/A N/A | V2: #N/A N/A | W2: #N/A N/A | X2: #N/A N/A
A3: 9903115D UN Equity | B3: Financials | C3: #N/A N/A | D3: #N/A N/A | E3: #N/A N/A | F3: #N/A N/A | G3: #N/A N/A | H3: #N/A N/A | I3: #N/A N/A | J3: #N/A N/A | K3: #N/A N/A | L3: #N/A N/A | M3: #N/A N/A | N3: #N/A N/A | O3: #N/A N/A | P3: #N/A N/A | Q3: #N/A N/A | R3: #N/A N/A | S3: #N/A N/A | T3: #N/A N/A | U3: #N/A N/A | V3: #N/A N/A | W3: #N/A N/A | X3: #N/A N/A | AC3: 22.2422 | AD3: 16.7841
A4: A UN Equity | B4: Health Care | C4: 16.7841 | D4: 19.3151 | E4: 19.9456 | F4: 23.5821 | G4: 24.2016 | H4: 25.4329 | I4: 26.4621 | J4: 23.4524 | K4: 24.5842 | L4: 24.7822 | M4: 21.279 | N4: 22.2422 | O4: 20.9545 | P4: 20.7086 | Q4: 24.6575 | R4: 21.9535 | S4: 20.614 | T4: 18.8826 | U4: 19.881 | V4: 20.6187 | W4: 19.9459 | X4: 19.9459 | AD4: 16.7841
A5: 9980328D UN Equity | B5: Health Care | C5: #N/A N/A | D5: #N/A N/A | E5: #N/A N/A | F5: #N/A N/A | G5: 82.6726 | H5: #N/A N/A | I5: #N/A N/A | J5: #N/A N/A | K5: 51.0539 | L5: #N/A N/A | M5: #N/A N/A | N5: #N/A N/A | O5: #N/A N/A | P5: #N/A N/A | Q5: #N/A N/A | R5: #N/A N/A | S5: 88.5754 | T5: #N/A N/A | U5: #N/A N/A | V5: #N/A N/A | W5: #N/A N/A | X5: #N/A N/A | AA5: 24.6575 | AB5: 45295 | AC5: 131
A6: AAPL UW Equity | B6: Information Technology | C6: 103.4003 | D6: 127.1247 | E6: 147.4433 | F6: 145.5673 | G6: 20.309 | H6: 162.8163 | I6: 175.4593 | J6: 147.943 | K6: 40.4676 | L6: 145.6054 | M6: 171.9495 | N6: 154.2694 | O6: 147.2498 | P6: 160.5834 | Q6: 157.4125 | R6: 136.5205 | S6: 32.0596 | T6: 149.8136 | U6: 171.4224 | V6: 152.0213 | W6: #N/A N/A | X6: #N/A N/A | Y6: 45294 | Z6: 184.25 | AA6: 21.9535 | AB6: 45296 | AC6: 130.56
A7: 9983490D UN Equity | B7: Information Technology | C7: 17.9492 | D7: #N/A N/A | E7: #N/A N/A | F7: #N/A N/A | G7: 22.404 | H7: #N/A N/A | I7: #N/A N/A | J7: #N/A N/A | K7: 16.0312 | L7: #N/A N/A | M7: #N/A N/A | N7: #N/A N/A | O7: #N/A N/A | P7: #N/A N/A | Q7: #N/A N/A | R7: #N/A N/A | S7: 30.8191 | T7: #N/A N/A | U7: #N/A N/A | V7: #N/A N/A | W7: #N/A N/A | X7: #N/A N/A | Y7: 45295 | Z7: 181.91 | AA7: 45299 | AB7: 45299 | AC7: 133.38
A8: ABBV UN Equity | B8: Health Care | C8: #N/A N/A | D8: 48.3484 | E8: 51.7765 | F8: 80.4592 | G8: 80.4592 | H8: 92.3738 | I8: 90.3466 | J8: 72.1634 | K8: 72.1634 | L8: 62.7494 | M8: 46.0695 | N8: 34.9026 | O8: 55.9184 | P8: 53.93 | Q8: 56.1735 | R8: 62.0826 | S8: 62.0826 | T8: #N/A N/A | U8: #N/A N/A | V8: #N/A N/A | W8: #N/A N/A | X8: #N/A N/A | Y8: 45296 | Z8: 181.18 | AA8: 45300 | AB8: 45300 | AC8: 130.68
A9: 9990213D UN Equity | B9: Industrials | C9: 14.1371 | D9: 10.2853 | E9: 8.6061 | F9: 5.8181 | G9: 15.1737 | H9: 7.1453 | I9: #N/A N/A | J9: #N/A N/A | K9: 15.4919 | L9: #N/A N/A | M9: #N/A N/A | N9: #N/A N/A | O9: #N/A N/A | P9: #N/A N/A | Q9: #N/A N/A | R9: #N/A N/A | S9: 18.9899 | T9: #N/A N/A | U9: #N/A N/A | V9: #N/A N/A | W9: #N/A N/A | X9: #N/A N/A | Y9: 45299 | Z9: 185.56 | AA9: 45301 | AB9: 45301 | AC9: 131.09
A10: 9991429D UN Equity | B10: Consumer Discretionary | C10: #N/A N/A | D10: #N/A N/A | E10: #N/A N/A | F10: #N/A N/A | G10: #N/A N/A | H10: #N/A N/A | I10: #N/A N/A | J10: 16.8653 | K10: #N/A N/A | L10: #N/A N/A | M10: #N/A N/A | N10: 1.1618 | O10: #N/A N/A | P10: #N/A N/A | Q10: #N/A N/A | R10: -14.3199 | S10: #N/A N/A | T10: #N/A N/A | U10: #N/A N/A | V10: #N/A N/A | W10: #N/A N/A | X10: #N/A N/A | Y10: 45300 | Z10: 185.14 | AA10: 45302 | AB10: 45302 | AC10: 129.68
A11: ABNB UW Equity | B11: Consumer Discretionary | C11: #N/A N/A | D11: #N/A N/A | E11: #N/A N/A | F11: -9.1584 | G11: -9.1584 | H11: 28.9166 | I11: 32.6224 | J11: 36.6393 | K11: 36.6393 | L11: 44.6483 | M11: 74.4725 | N11: 69.8288 | O11: 74.9071 | P11: 74.175 | Q11: 20.8733 | R11: 31.9479 | S11: 31.9479 | T11: 33.2615 | U11: 30.7755 | V11: 30.233 | W11: 30.233 | X11: 30.233 | Y11: 45301 | Z11: 186.19 | AA11: 45303 | AB11: 45303 | AC11: 130.54
A12: ABT UN Equity | B12: Health Care | C12: 14.075 | D12: 19.808 | E12: 22.0156 | F12: 20.6194 | G12: 20.6194 | H12: 24.3392 | I12: 22.5088 | J12: 19.1287 | K12: 19.1287 | L12: 14.0123 | M12: 14.1123 | N12: 15.2028 | O12: 14.851 | P12: 14.5296 | Q12: 14.9255 | R12: 31.071 | S12: 31.071 | T12: 31.1049 | U12: 30.8033 | V12: 13.0749 | W12: 13.0749 | X12: 13.0749 | Y12: 45302 | Z12: 185.59 | AA12: 45307 | AB12: 45307 | AC12: 130.53
A13: AAL UW Equity | B13: Industrials | C13: #N/A N/A | D13: #N/A N/A | E13: #N/A N/A | F13: #N/A N/A | G13: #N/A N/A | H13: #N/A N/A | I13: #N/A N/A | J13: #N/A N/A | K13: #N/A N/A | L13: #N/A N/A | M13: #N/A N/A | N13: #N/A N/A | O13: #N/A N/A | P13: #N/A N/A | Q13: #N/A N/A | R13: #N/A N/A | S13: #N/A N/A | T13: #N/A N/A | U13: #N/A N/A | V13: #N/A N/A | W13: #N/A N/A | X13: #N/A N/A | Y13: 45303 | Z13: 185.92 | AA13: 45308 | AB13: 45308 | AC13: 128.12
A14: ACGL UW Equity | B14: Financials | C14: 10.4038 | D14: 17.0027 | E14: 16.25 | F14: 16.3578 | G14: 13.7962 | H14: 13.0239 | I14: 10.205 | J14: 11.5879 | K14: 18.3442 | L14: 17.501 | M14: 23.0826 | N14: 29.7469 | O14: 30.3487 | P14: 32.1346 | Q14: 31.6347 | R14: 22.7761 | S14: 6.0259 | T14: 17.5712 | U14: 18.2979 | V14: 20.1033 | W14: 20.1033 | X14: 20.1033 | Y14: 45307 | Z14: 183.63 | AA14: 45309 | AB14: 45309 | AC14: 130.46
A15: AAP UN Equity | B15: Consumer Discretionary | C15: 44.2792 | D15: 18.0537 | E15: 17.7601 | F15: 18.5779 | G15: 58.0046 | H15: 17.7803 | I15: 17.5736 | J15: 16.2955 | K15: 82.686 | L15: 14.119 | M15: 11.8045 | N15: 5.5107 | O15: #N/A N/A | P15: 0.8234 | Q15: -0.4565 | R15: 1.6731 | S15: 76.2889 | T15: -14.7754 | U15: -15.8751 | V15: -15.723 | W15: 2.0147 | X15: 2.0147 | Y15: 45308 | Z15: 182.68 | AA15: 45310 | AB15: 45310 | AC15: 131.22
A16: ACN UN Equity | B16: Information Technology | C16: 32.3081 | D16: 32.6861 | E16: 32.3395 | F16: 32.3973 | G16: 32.8889 | H16: 32.5459 | I16: 33.0351 | J16: 32.5477 | K16: 31.3149 | L16: 30.6656 | M16: 28.7519 | N16: 27.7134 | O16: 27.6356 | P16: 26.2014 | Q16: 26.9158 | R16: 27.1008 | S16: 27.2613 | T16: 27.2689 | U16: 25.8168 | V16: 25.3458 | W16: #N/A N/A | X16: #N/A N/A | Y16: 45309 | Z16: 188.63 | AA16: 45313 | AB16: 45313 | AC16: 132.55
A17: ADBE UW Equity | B17: Information Technology | C17: 11.1182 | D17: 45.1381 | E17: 44.6971 | F17: 34.368 | G17: 35.3355 | H17: 35.1259 | I17: 33.4387 | J17: 32.9728 | K17: 10.6403 | L17: 33.6814 | M17: 33.9713 | N17: 35.5131 | O17: 32.367 | P17: 34.2239 | Q17: 35.355 | R17: 36.3126 | S17: 10.2274 | T17: 52.2536 | U17: 52.8748 | V17: 55.426 | W17: 58.7736 | X17: 58.7736 | Y17: 45310 | Z17: 191.56 | AA17: 45314 | AB17: 45314 | AC17: 131.64
A18: ADI UW Equity | B18: Information Technology | C18: 11.1733 | D18: 13.1376 | E18: 14.1527 | F18: 5.5627 | G18: 11.7118 | H18: 6.6671 | I18: 7.7216 | J18: 7.3829 | K18: 8.352 | L18: 9.9144 | M18: 10.3453 | N18: 9.2033 | O18: 7.8131 | P18: 6.0072 | Q18: 4.6576 | R18: 4.6232 | S18: 10.3874 | T18: 5.2132 | U18: 5.6518 | V18: 6.5728 | W18: 7.8622 | X18: 7.8622 | Y18: 45313 | Z18: 193.89 | AA18: 45315 | AB18: 45315 | AC18: 129.78
A19: ADM UN Equity | B19: Consumer Staples | C19: -10.0964 | D19: 11.3174 | E19: 12.6614 | F19: 12.7551 | G19: -6.4317 | H19: 15.652 | I19: 17.8523 | J19: 18.5625 | K19: -27.3458 | L19: 16.8126 | M19: 15.9959 | N19: 14.3878 | O19: 12.6542 | P19: 11.0476 | Q19: 7.6183 | R19: 7.7754 | S19: 43.7186 | T19: 4.9307 | U19: 5.3479 | V19: 4.8017 | W19: 4.8017 | X19: 4.8017 | Y19: 45314 | Z19: 195.18 | AA19: 45316 | AB19: 45316 | AC19: 129.88
A20: ABMD UW Equity | B20: Health Care | C20: 18.8189 | D20: 12.8176 | E20: 11.6209 | F20: 9.8751 | G20: 13.2371 | H20: 15.3028 | I20: 18.2443 | J20: #N/A N/A | K20: 18.4908 | L20: #N/A N/A | M20: #N/A N/A | N20: #N/A N/A | O20: #N/A N/A | P20: #N/A N/A | Q20: #N/A N/A | R20: #N/A N/A | S20: 14.408 | T20: #N/A N/A | U20: #N/A N/A | V20: #N/A N/A | W20: #N/A N/A | X20: #N/A N/A | Y20: 45315 | Z20: 194.5 | AA20: 45317 | AB20: 45317 | AC20: 130.99
A21: ADP UW Equity | B21: Industrials | C21: -6.3126 | D21: 45.4987 | E21: 48.3333 | F21: 50.1169 | G21: 16.3473 | H21: 66.2994 | I21: 76.3775 | J21: 78.2947 | K21: 12.8313 | L21: 101.3275 | M21: 115.4613 | N21: 97.3844 | O21: 88.9225 | P21: 93.1399 | Q21: 87.2628 | R21: 83.7162 | S21: -4.559 | T21: 76.0013 | U21: 70.5709 | V21: 73.8395 | W21: 73.8395 | X21: 73.8395 | Y21: 45316 | Z21: 194.17 | AA21: 45320 | AB21: 45320 | AC21: 132.83
A22: ADSK UW Equity | B22: Information Technology | C22: 7.914 | D22: #N/A N/A | E22: 188.5313 | F22: 195.6567 | G22: 54.8551 | H22: 53.9074 | I22: 53.9801 | J22: 56.6449 | K22: 5.1224 | L22: 106.2104 | M22: 89.8253 | N22: 76.8007 | O22: 60.4 | P22: 65.206 | Q22: 57.4457 | R22: 53.2455 | S22: 13.2044 | T22: 42.3608 | U22: 40.2004 | V22: 40.334 | W22: 39.6753 | X22: 39.6753 | Y22: 45317 | Z22: 192.42 | AA22: 45321 | AB22: 45321 | AC22: 134.28
A23: AEE UN Equity | B23: Utilities | C23: 14.5333 | D23: #N/A N/A | E23: #N/A N/A | F23: #N/A N/A | G23: 12.2566 | H23: 10.4924 | I23: 10.4194 | J23: 10.6295 | K23: 12.357 | L23: 10.8471 | M23: 10.8925 | N23: 10.5412 | O23: 10.4218 | P23: 10.5235 | Q23: 9.9056 | R23: 10.0754 | S23: 9.2722 | T23: 10.288 | U23: 11.4655 | V23: 11.4129 | W23: 11.4129 | X23: 11.4129 | Y23: 45320 | Z23: 191.73 | AA23: 45322 | AB23: 45322 | AC23: 130.1
A24: AEP UW Equity | B24: Utilities | C24: 14.7519 | D24: 11.2586 | E24: 11.1461 | F24: 11.5531 | G24: 14.5983 | H24: 11.299 | I24: 10.5424 | J24: 9.9414 | K24: 11.0743 | L24: 8.2611 | M24: 9.0726 | N24: 6.2594 | O24: 8.6478 | P24: 7.8388 | Q24: 7.5739 | R24: 11.3518 | S24: 9.8211 | T24: 12.77 | U24: 12.8195 | V24: #N/A N/A | W24: #N/A N/A | X24: #N/A N/A | Y24: 45321 | Z24: 188.04 | AA24: 45323 | AB24: 45323 | AC24: 133.05
A25: AES UN Equity | B25: Utilities | C25: 7.569 | D25: -5.7643 | E25: 24.3529 | F25: -17.7556 | G25: 4.8627 | H25: -16.1224 | I25: -10.978 | J25: -30.5711 | K25: 48.872 | L25: -19.4175 | M25: -24.8227 | N25: 15.3278 | O25: 23.9602 | P25: 35.8693 | Q25: 42.9746 | R25: 67.1704 | S25: -15.2985 | T25: 31.1146 | U25: 31.7261 | V25: 23.3554 | W25: 23.3554 | X25: 23.3554 | Y25: 45322 | Z25: 184.4 | AA25: 45324 | AB25: 45324 | AC25: 132.97
A26: AFL UN Equity | B26: Financials | C26: 14.6683 | D26: 18.3833 | E26: 12.8334 | F26: 12.9468 | G26: 19.9971 | H26: 14.5305 | I26: 18.2344 | J26: 16.549 | K26: 8.8171 | L26: 20.4972 | M26: 19.5938 | N26: 22.1199 | O26: 24.6993 | P26: 23.5383 | Q26: 16.0382 | R26: 22.64 | S26: 10.8435 | T26: 9.1536 | U26: 15.5798 | V26: 13.1179 | W26: 13.1179 | X26: 13.1179 | Y26: 45323 | Z26: 186.86 | AA26: 45327 | AB26: 45327 | AC26: 132.82
A27: AIG UN Equity | B27: Financials | C27: 15.1762 | D27: 6.5679 | E27: 8.6895 | F27: 14.2539 | G27: 15.4385 | H27: 22.8078 | I27: 26.3547 | J27: 19.7874 | K27: -13.002 | L27: 11.0463 | M27: 10.3258 | N27: 8.4715 | O27: 11.1666 | P27: -1.5671 | Q27: -5.2956 | R27: -3.283 | S27: 21.4625 | T27: 7.4442 | U27: 7.5682 | V27: 7.4459 | W27: 7.4459 | X27: 7.4459 | Y27: 45324 | Z27: 185.85 | AA27: 45328 | AB27: 45328 | AC27: 135.86
A28: AIZ UN Equity | B28: Financials | C28: 63.0172 | D28: 8.0044 | E28: 24.2476 | F28: #N/A N/A | G28: 63.6902 | H28: 23.2868 | I28: 6.7477 | J28: 5.7073 | K28: 54.7861 | L28: 7.7199 | M28: 12.2964 | N28: 14.2174 | O28: 16.4291 | P28: 16.8108 | Q28: 15.2146 | R28: 15.3325 | S28: 42.0515 | T28: 13.6535 | U28: 15.4134 | V28: 15.8986 | W28: 15.8986 | X28: 15.8986 | Y28: 45327 | Z28: 187.68 | AA28: 45329 | AB28: 45329 | AC28: 132.79
A29: AJG UN Equity | B29: Financials | C29: 14.4388 | D29: 12.9133 | E29: 13.2414 | F29: 12.3419 | G29: 12.3419 | H29: 12.3518 | I29: 12.8057 | J29: 12.6241 | K29: 12.6241 | L29: 11.5838 | M29: 11.9471 | N29: 9.7345 | O29: 10.3359 | P29: 10.3814 | Q29: 10.3517 | R29: 9.4585 | S29: 9.4585 | T29: 9.4873 | U29: 9.0489 | V29: 6.8725 | W29: 6.8725 | X29: 6.8725 | Y29: 45328 | Z29: 189.3 | AA29: 45330 | AB29: 45330 | AC29: 134.07
A30: AKAM UW Equity | B30: Information Technology | C30: 18.39 | D30: 13.9408 | E30: 13.9119 | F30: 14.8416 | G30: 20.7551 | H30: 13.5287 | I30: 12.1861 | J30: 11.3691 | K30: 22.2932 | L30: 11.1645 | M30: 12.0417 | N30: 12.2275 | O30: 14.2177 | P30: 13.9059 | Q30: 11.5411 | R30: 10.6573 | S30: 20.7056 | T30: 9.2083 | U30: 10.6416 | V30: 9.173 | W30: 9.173 | X30: 9.173 | Y30: 45329 | Z30: 189.41 | AA30: 45331 | AB30: 45331 | AC30: 133.34
A31: ALB UN Equity | B31: Materials | C31: 9.1644 | D31: 13.802 | E31: 4.3208 | F31: 2.5001 | G31: 2.5001 | H31: 4.3026 | I31: 25.0033 | J31: 39.5332 | K31: 39.5332 | L31: 49.2847 | M31: 39.9701 | N31: 18.0913 | O31: 3.5198 | P31: -5.915 | Q31: -22.0578 | R31: -15.4166 | S31: -15.4166 | T31: -13.0012 | U31: -2.3935 | V31: -9.0954 | W31: -9.0954 | X31: -9.0954 | Y31: 45330 | Z31: 188.32 | AA31: 45334 | AB31: 45334 | AC31: 132.31
A32: ALGN UW Equity | B32: Health Care | C32: -35.5007 | D32: 22.4241 | E32: 22.5961 | F32: 22.5191 | G32: 14.312 | H32: 17.7283 | I32: 14.1654 | J32: 10.0102 | K32: 1.6107 | L32: 8.6796 | M32: 9.6796 | N32: 12.3081 | O32: 12.7704 | P32: 12.0882 | Q32: 11.4009 | R32: 11.2626 | S32: 8.8982 | T32: 11.4099 | U32: 9.5775 | V32: 10.3871 | W32: 10.3871 | X32: 10.3871 | Y32: 45331 | Z32: 188.85 | AA32: 45335 | AB32: 45335 | AC32: 129.76
A33: ALL UN Equity | B33: Financials | C33: 14.1709 | D33: 14.7033 | E33: 12.4872 | F33: 5.7843 | G33: 15.9858 | H33: 3.8546 | I33: -1.5365 | J33: -7.2662 | K33: 16.241 | L33: -17.3147 | M33: -14.7494 | N33: -2.0267 | O33: 7.605 | P33: 19.3869 | Q33: 26.2098 | R33: 25.9171 | S33: 14.9638 | T33: 29.6271 | U33: 37.3109 | V33: 42.3966 | W33: 42.3966 | X33: 42.3966 | Y33: 45334 | Z33: 187.15 | AA33: 45336 | AB33: 45336 | AC33: 132.24
A34: ALLE UN Equity | B34: Industrials | C34: 75.2962 | D34: 63.8933 | E34: 54.9008 | F34: 60.7995 | G34: 111.6683 | H34: 59.4913 | I34: 52.6004 | J34: 53.8538 | K34: 252.7778 | L34: 53.8136 | M34: 55.0657 | N34: 47.8209 | O34: 45.1977 | P34: 43.2232 | Q34: 40.812 | R34: 42.3909 | S34: 105.6728 | T34: 38.9937 | U34: 36.4112 | V34: 36.0844 | W34: 36.0844 | X34: 36.0844 | Y34: 45335 | Z34: 185.04 | AA34: 45337 | AB34: 45337 | AC34: 134.75
A35: AMAT UW Equity | B35: Information Technology | C35: -1.066 | D35: 42.1754 | E35: 49.073 | F35: 51.5926 | G35: 58.6758 | H35: 57.3222 | I35: 55.085 | J35: 53.3939 | K35: 56.4999 | L35: 50.4823 | M35: 47.4395 | N35: 48.0398 | O35: 46.4067 | P35: 45.193 | Q35: 43.9101 | R35: 40.6054 | S35: 58.1077 | T35: 36.3724 | U35: 35.6353 | V35: 35.5084 | W35: 38.8627 | X35: 38.8627 | Y35: 45336 | Z35: 184.15 | AA35: 45338 | AB35: 45338 | AC35: 134.84
A36: AMCR UN Equity | B36: Materials | C36: 51.0947 | D36: 20.0002 | E36: 20.1992 | F36: 20.51 | G36: 56.9822 | H36: 18.2003 | I36: 19.4911 | J36: 24.2541 | K36: 25.8115 | L36: 25.8757 | M36: 24.7953 | N36: 15.4864 | O36: 15.9668 | P36: 18.4647 | Q36: 19.6751 | R36: 20.5989 | S36: 48.1708 | T36: 6.5475 | U36: 7.4439 | V36: 7.7302 | W36: 7.7302 | X36: 7.7302 | Y36: 45337 | Z36: 183.86 | AA36: 45342 | AB36: 45342 | AC36: 134.14
A37: AMD UW Equity | B37: Information Technology | C37: 31.9149 | D37: 66.2681 | E37: 72.144 | F37: 47.4276 | G37: 18.0456 | H37: 10.0588 | I37: 7.3705 | J37: 4.2412 | K37: 2.9765 | L37: 0.718 | M37: 0.3799 | N37: 1.5437 | O37: 2.0128 | P37: 2.4249 | Q37: 3.262 | R37: 2.8926 | S37: 25.2404 | T37: 4.8777 | U37: 5.6141 | V37: 7.191 | W37: #N/A N/A | X37: #N/A N/A | Y37: 45338 | Z37: 182.31 | AA37: 45343 | AB37: 45343 | AC37: 135.33
A38: ALK UN Equity | B38: Industrials | C38: 21.4754 | D38: -17.0355 | E38: 0.3722 | F38: 14.0816 | G38: 24.5314 | H38: 5.8402 | I38: 1.468 | J38: 1.5229 | K38: 31.9891 | L38: 4.129 | M38: 6.5412 | N38: 5.9276 | O38: 6.3919 | P38: 5.5032 | Q38: 7.5128 | R38: 9.3105 | S38: 33.681 | T38: 7.6641 | U38: 3.5261 | V38: 2.3557 | W38: 2.3557 | X38: 2.3557 | Y38: 45342 | Z38: 181.56 | AA38: 45344 | AB38: 45344 | AC38: 132.02
A39: AME UN Equity | B39: Industrials | C39: 12.4311 | D39: 14.8189 | E39: 15.1583 | F39: 15.444 | G39: 10.6942 | H39: 16.4587 | I39: 16.5676 | J39: 16.1627 | K39: 12.1001 | L39: 16.4279 | M39: 16.5091 | N39: 16.2055 | O39: 15.7655 | P39: 15.3672 | Q39: 14.8857 | R39: 14.9697 | S39: 10.2299 | T39: 14.6389 | U39: 14.6316 | V39: 14.5941 | W39: 14.5941 | X39: 14.5941 | Y39: 45343 | Z39: 182.32 | AA39: 45345 | AB39: 45345 | AC39: 132.03
A40: AMGN UW Equity | B40: Health Care | C40: 56.8313 | D40: 60.7849 | E40: 58.5002 | F40: 73.1641 | G40: 50.2115 | H40: 123.3077 | I40: 115.1643 | J40: 126.4743 | K40: 126.4743 | L40: 173.4565 | M40: 133.8049 | N40: 135.793 | O40: 72.5747 | P40: 49.2681 | Q40: 55.7202 | R40: 67.5531 | S40: 67.5531 | T40: 99.1388 | U40: 81.71 | V40: 106.1025 | W40: 106.1025 | X40: 106.1025 | Y40: 45344 | Z40: 184.37 | AA40: 45348 | AB40: 45348 | AC40: 131.49
...

Sheet IMPLIEDREVISION
A1: BEST_TARGET_PRICE | B1: SPX Index | C1: 2499073D UN Equity | D1: 9903115D UN Equity | E1: A UN Equity | F1: 9980328D UN Equity | G1: AAPL UW Equity | H1: 9983490D UN Equity | I1: ABBV UN Equity | J1: 9990213D UN Equity | K1: 9991429D UN Equity | L1: ABNB UW Equity | M1: ABT UN Equity | N1: AAL UW Equity | O1: ACGL UW Equity | P1: AAP UN Equity | Q1: ACN UN Equity | R1: ADBE UW Equity | S1: ADI UW Equity | T1: ADM UN Equity | U1: ABMD UW Equity | V1: ADP UW Equity | W1: ADSK UW Equity | X1: AEE UN Equity | Y1: AEP UW Equity | Z1: AES UN Equity | AA1: AFL UN Equity | AB1: AIG UN Equity | AC1: AIZ UN Equity | AD1: AJG UN Equity | AE1: AKAM UW Equity | AF1: ALB UN Equity | AG1: ALGN UW Equity | AH1: ALL UN Equity | AI1: ALLE UN Equity | AJ1: AMAT UW Equity | AK1: AMCR UN Equity | AL1: AMD UW Equity | AM1: ALK UN Equity | AN1: AME UN Equity | AO1: AMGN UW Equity | AP1: AMP UN Equity | AQ1: AMT UN Equity | AR1: AMZN UW Equity | AS1: ALXN UW Equity | AT1: ANET UN Equity | AU1: ANSS UW Equity | AV1: AON UN Equity | AW1: AOS UN Equity | AX1: APA UW Equity | AY1: APD UN Equity | AZ1: APH UN Equity | BA1: APO UN Equity | BB1: APP UW Equity | BC1: APTV UN Equity | BD1: ARE UN Equity | BE1: ATO UN Equity | BF1: ARES UN Equity | BG1: AVB UN Equity | BH1: AVGO UW Equity | BI1: AVY UN Equity | BJ1: AWK UN Equity | BK1: ATVI UW Equity | BL1: AXON UW Equity | BM1: AXP UN Equity | BN1: AZO UN Equity | BO1: BA UN Equity | BP1: BAC UN Equity | BQ1: BALL UN Equity | BR1: BAX UN Equity | BS1: BBY UN Equity | BT1: BDX UN Equity | BU1: BEN UN Equity | BV1: BBWI UN Equity | BW1: BF/B UN Equity | BX1: BG UN Equity | BY1: BIIB UW Equity | BZ1: BK UN Equity | CA1: BKNG UW Equity | CB1: BKR UW Equity | CC1: BLDR UN Equity | CD1: BIO UN Equity | CE1: BLK UN Equity | CF1: BMY UN Equity | CG1: BR UN Equity | CH1: BRK/B UN Equity | CI1: BRO UN Equity | CJ1: BSX UN Equity | CK1: BKR UN Equity | CL1: BWA UN Equity | CM1: BX UN Equity | CN1: BXP UN Equity | CO1: C UN Equity | CP1: CAG UN Equity | CQ1: CAH UN Equity | CR1: CARR UN Equity | CS1: CAT UN Equity | CT1: CB UN Equity | CU1: CBOE UF Equity | CV1: CBRE UN Equity | CW1: CCI UN Equity | CX1: CCL UN Equity | CY1: CDNS UW Equity | CZ1: CDW UW Equity | DA1: CE UN Equity | DB1: CEG UW Equity | DC1: CF UN Equity | DD1: CFG UN Equity | DE1: CHD UN Equity | DF1: CHRW UW Equity | DG1: CERN UW Equity | DH1: CHTR UW Equity | DI1: CI UN Equity | DJ1: CIEN UN Equity | DK1: CINF UW Equity | DL1: CL UN Equity | DM1: CLX UN Equity | DN1: CMCSA UW Equity | DO1: CME UW Equity | DP1: CMG UN Equity | DQ1: CMA UN Equity | DR1: CMI UN Equity | DS1: CMS UN Equity | DT1: CNC UN Equity | DU1: CNP UN Equity | DV1: COF UN Equity | DW1: COO UW Equity | DX1: COIN UW Equity | DY1: COP UN Equity | DZ1: COR UN Equity | EA1: COST UW Equity | EB1: COO UN Equity | EC1: CPAY UN Equity | ED1: CPB UW Equity | EE1: CPRT UW Equity | EF1: CPT UN Equity | EG1: CRL UN Equity | EH1: CPB UN Equity | EI1: CRM UN Equity | EJ1: CRH UN Equity | EK1: CRWD UW Equity | EL1: CSCO UW Equity | EM1: CSGP UW Equity | EN1: CSX UW Equity | EO1: CTAS UW Equity | EP1: CTRA UN Equity | EQ1: CTLT UN Equity | ER1: CTSH UW Equity | ES1: CTVA UN Equity | ET1: CVS UN Equity | EU1: CVX UN Equity | EV1: CTXS UW Equity | EW1: CZR UW Equity | EX1: CVNA UN Equity | EY1: D UN Equity | EZ1: DAL UN Equity | FA1: DAY UN Equity | FB1: DD UN Equity | FC1: DE UN Equity | FD1: DASH UW Equity | FE1: DECK UN Equity | FF1: DFS UN Equity | FG1: DELL UN Equity | FH1: DDOG UW Equity | FI1: DG UN Equity | FJ1: DGX UN Equity | FK1: DHI UN Equity | FL1: DHR UN Equity | FM1: DIS UN Equity | FN1: DISCA UW Equity | FO1: DISCK UW Equity | FP1: DLR UN Equity | FQ1: DISH UW Equity | FR1: DLTR UW Equity | FS1: DOC UN Equity | FT1: DOV UN Equity | FU1: DOW UN Equity | FV1: DPZ UW Equity | FW1: DOC US Equity | FX1: DRI UN Equity | FY1: DPZ UN Equity | FZ1: DTE UN Equity | GA1: DRE UN Equity | GB1: DUK UN Equity | GC1: DVA UN Equity | GD1: DVN UN Equity | GE1: DXCM UW Equity | GF1: EA UW Equity | GG1: EBAY UW Equity | GH1: DXC UN Equity | GI1: ECL UN Equity | GJ1: ED UN Equity | GK1: EFX UN Equity | GL1: EG UN Equity | GM1: EIX UN Equity | GN1: EL UN Equity | GO1: ELV UN Equity | GP1: EMN UN Equity | GQ1: EMR UN Equity | GR1: ENPH UQ Equity | GS1: EME UN Equity | GT1: EOG UN Equity | GU1: EPAM UN Equity | GV1: EQIX UW Equity | GW1: EQR UN Equity | GX1: EQT UN Equity | GY1: ERIE UW Equity | GZ1: ES UN Equity | HA1: ESS UN Equity | HB1: ETN UN Equity | HC1: ETR UN Equity | HD1: EVRG UW Equity | HE1: ETSY UW Equity | HF1: EW UN Equity | HG1: EVRG UN Equity | HH1: EXC UW Equity | HI1: EXPD UN Equity | HJ1: EXPE UW Equity | HK1: EXE UW Equity | HL1: EXPD UW Equity | HM1: EXR UN Equity | HN1: F UN Equity | HO1: FANG UW Equity | HP1: FAST UW Equity | HQ1: FCX UN Equity | HR1: FDS UN Equity | HS1: FBIN UN Equity | HT1: FDX UN Equity | HU1: FE UN Equity | HV1: FFIV UW Equity | HW1: FICO UN Equity | HX1: FIS UN Equity | HY1: FISV UN Equity | HZ1: FISV UW Equity | IA1: FITB UW Equity | IB1: FMC UN Equity | IC1: FLIR UW Equity | ID1: FOX UW Equity | IE1: FLS UN Equity | IF1: FOXA UW Equity | IG1: FIX UN Equity | IH1: FRT UN Equity | II1: FSLR UW Equity | IJ1: FTNT UW Equity | IK1: FRCB UN Equity | IL1: FTV UN Equity | IM1: GD UN Equity | IN1: GDDY UN Equity | IO1: GE UN Equity | IP1: GAP UN Equity | IQ1: GEHC UW Equity | IR1: GEN UW Equity | IS1: GEV UN Equity | IT1: GILD UW Equity | IU1: GIS UN Equity | IV1: GL UN Equity | IW1: GLW UN Equity | IX1: GM UN Equity | IY1: GNRC UN Equity | IZ1: GOOG UW Equity | JA1: GOOGL UW Equity | JB1: GPC UN Equity | JC1: GPN UN Equity | JD1: GRMN UW Equity | JE1: GRMN UN Equity | JF1: GS UN Equity | JG1: GWW UN Equity | JH1: HAL UN Equity | JI1: HAS UW Equity | JJ1: HBAN UW Equity | JK1: HBI UN Equity | JL1: HCA UN Equity | JM1: HD UN Equity | JN1: HES UN Equity | JO1: HIG UN Equity | JP1: HFC UN Equity | JQ1: HII UN Equity | JR1: HLT UN Equity | JS1: HOLX UW Equity | JT1: HON UW Equity | JU1: HPE UN Equity | JV1: HON UN Equity | JW1: HPQ UN Equity | JX1: HOOD UW Equity | JY1: HRL UN Equity | JZ1: HSIC UW Equity | KA1: HST UW Equity | KB1: HSY UN Equity | KC1: HUBB UN Equity | KD1: HUM UN Equity | KE1: HWM UN Equity | KF1: IBM UN Equity | KG1: ICE UN Equity | KH1: IDXX UW Equity | KI1: IBKR UW Equity | KJ1: IEX UN Equity | KK1: IFF UN Equity | KL1: INCY UW Equity | KM1: ILMN UW Equity | KN1: INTC UW Equity | KO1: INTU UW Equity | KP1: INVH UN Equity | KQ1: IP UN Equity | KR1: IPG UN Equity | KS1: IQV UN Equity | KT1: IPGP UW Equity | KU1: IR UN Equity | KV1: IRM UN Equity | KW1: ISRG UW Equity | KX1: IT UN Equity | KY1: ITW UN Equity | KZ1: IVZ UN Equity | LA1: J UN Equity | LB1: JBHT UW Equity | LC1: JBL UN Equity | LD1: JCI UN Equity | LE1: JKHY UW Equity | LF1: JNJ UN Equity | LG1: JNPR UN Equity | LH1: JPM UN Equity | LI1: K UN Equity | LJ1: KEY UN Equity | LK1: KDP UW Equity | LL1: KEYS UN Equity | LM1: KHC UW Equity | LN1: KIM UN Equity | LO1: KLAC UW Equity | LP1: KMB UN Equity | LQ1: KKR UN Equity | LR1: KMI UN Equity | LS1: KMX UN Equity | LT1: KMB UW Equity | LU1: KO UN Equity | LV1: KR UN Equity | LW1: KSU UN Equity | LX1: L UN Equity | LY1: KVUE UN Equity | LZ1: LDOS UN Equity | MA1: LEG UN Equity | MB1: LEN UN Equity | MC1: LHX UN Equity | MD1: LIN UN Equity | ME1: LH UN Equity | MF1: LKQ UW Equity | MG1: LLY UN Equity | MH1: LII UN Equity | MI1: LMT UN Equity | MJ1: LIN UW Equity | MK1: LNC UN Equity | ML1: LNT UW Equity | MM1: LOW UN Equity | MN1: LRCX UW Equity | MO1: LUMN UN Equity | MP1: LUV UN Equity | MQ1: LULU UW Equity | MR1: LVS UN Equity | MS1: LW UN Equity | MT1: LYB UN Equity | MU1: LYV UN Equity | MV1: MA UN Equity | MW1: MAA UN Equity | MX1: MAR UW Equity | MY1: MAS UN Equity | MZ1: MCD UN Equity | NA1: MCHP UW Equity | NB1: MCK UN Equity | NC1: MCO UN Equity | ND1: MDLZ UW Equity | NE1: MDT UN Equity | NF1: MET UN Equity | NG1: META UW Equity | NH1: MGM UN Equity | NI1: MHK UN Equity | NJ1: MKC UN Equity | NK1: MKTX UW Equity | NL1: MLM UN Equity | NM1: MMM UN Equity | NN1: MNST UW Equity | NO1: MO UN Equity | NP1: MOH UN Equity | NQ1: MOS UN Equity | NR1: MPC UN Equity | NS1: MPWR UW Equity | NT1: MRK UN Equity | NU1: MRNA UW Equity | NV1: MRO UN Equity | NW1: MRSH UN Equity | NX1: MS UN Equity | NY1: MSCI UN Equity | NZ1: MSFT UW Equity | OA1: MSI UN Equity | OB1: MTB UN Equity | OC1: MTCH UW Equity | OD1: MTD UN Equity | OE1: MU UW Equity | OF1: MXIM UW Equity | OG1: NCLH UN Equity | OH1: NDAQ UW Equity | OI1: NDSN UW Equity | OJ1: NEE UN Equity | OK1: NEM UN Equity | OL1: NFLX UW Equity | OM1: NI UN Equity | ON1: NKE UN Equity | OO1: NLSN UN Equity | OP1: NOC UN Equity | OQ1: NOW UN Equity | OR1: NOV UN Equity | OS1: NRG UN Equity | OT1: NSC UN Equity | OU1: NTAP UW Equity | OV1: NTRS UW Equity | OW1: NUE UN Equity | OX1: NVDA UW Equity | OY1: NVR UN Equity | OZ1: NWS UW Equity | PA1: NWSA UW Equity | PB1: NWL UW Equity | PC1: NXPI UW Equity | PD1: O UN Equity | PE1: ODFL UW Equity | PF1: OKE UN Equity | PG1: OMC UN Equity | PH1: ON UW Equity | PI1: ORCL UN Equity | PJ1: OGN UN Equity | PK1: ORLY UW Equity | PL1: OTIS UN Equity | PM1: OXY UN Equity | PN1: PANW UW Equity | PO1: PARA UW Equity | PP1: PAYC UN Equity | PQ1: PAYX UW Equity | PR1: PCAR UW Equity | PS1: PBCT UW Equity | PT1: PCG UN Equity | PU1: PEG UN Equity | PV1: PEP UW Equity | PW1: PFE UN Equity | PX1: PFG UW Equity | PY1: PG UN Equity | PZ1: PENN UW Equity | QA1: PGR UN Equity | QB1: PH UN Equity | QC1: PHM UN Equity | QD1: PKG UN Equity | QE1: PLD UN Equity | QF1: PLTR UW Equity | QG1: PM UN Equity | QH1: PNC UN Equity | QI1: PNR UN Equity | QJ1: PNW UN Equity | QK1: POOL UW Equity | QL1: PODD UW Equity | QM1: PPG UN Equity | QN1: PPL UN Equity | QO1: PRGO UN Equity | QP1: PRU UN Equity | QQ1: PSA UN Equity | QR1: PSX UN Equity | QS1: PSKY UW Equity | QT1: PVH UN Equity | QU1: PWR UN Equity | QV1: PTC UW Equity | QW1: PXD UN Equity | QX1: PYPL UW Equity | QY1: QCOM UW Equity | QZ1: Q UN Equity | RA1: QRVO UW Equity | RB1: RCL UN Equity | RC1: REG UW Equity | RD1: REGN UW Equity | RE1: RF UN Equity | RF1: RHI UN Equity | RG1: RJF UN Equity | RH1: RL UN Equity | RI1: RMD UN Equity | RJ1: ROK UN Equity | RK1: ROL UN Equity | RL1: ROP UW Equity | RM1: ROP UN Equity | RN1: ROST UW Equity | RO1: RSG UN Equity | RP1: RTX UN Equity | RQ1: RVTY UN Equity | RR1: SBAC UW Equity | RS1: SBUX UW Equity | RT1: SCHW UN Equity | RU1: SHW UN Equity | RV1: SEE UN Equity | RW1: SJM UN Equity | RX1: SLB UN Equity | RY1: SIVBQ UW Equity | RZ1: SBNY UW Equity | SA1: SMCI UW Equity | SB1: SNA UN Equity | SC1: SEDG UW Equity | SD1: SNDK UW Equity | SE1: SLG UN Equity | SF1: SNPS UW Equity | SG1: SO UN Equity | SH1: SOLV UN Equity | SI1: SPG UN Equity | SJ1: SPGI UN Equity | SK1: SRE UN Equity | SL1: STE UN Equity | SM1: STLD UW Equity | SN1: STT UN Equity | SO1: STX UW Equity | SP1: STZ UN Equity | SQ1: SWK UN Equity | SR1: SW UN Equity | SS1: SWKS UW Equity | ST1: SYF UN Equity | SU1: SYK UN Equity | SV1: SYY UN Equity | SW1: T UN Equity | SX1: TAP UN Equity | SY1: TDG UN Equity | SZ1: TDY UN Equity | TA1: TER UW Equity | TB1: TFC UN Equity | TC1: TECH UW Equity | TD1: TFX UN Equity | TE1: TEL UN Equity | TF1: TGT UN Equity | TG1: TJX UN Equity | TH1: TMO UN Equity | TI1: TMUS UW Equity | TJ1: TPR UN Equity | TK1: TKO UN Equity | TL1: TRMB UW Equity | TM1: TROW UW Equity | TN1: TRV UN Equity | TO1: TPL UN Equity | TP1: TSCO UW Equity | TQ1: TSLA UW Equity | TR1: TRGP UN Equity | TS1: TSN UN Equity | TT1: TT UN Equity | TU1: TTWO UW Equity | TV1: TWTR UN Equity | TW1: TXN UW Equity | TX1: TXT UN Equity | TY1: TYL UN Equity | TZ1: UA UN Equity | UA1: TTD UQ Equity | UB1: UAA UN Equity | UC1: UAL UW Equity | UD1: UDR UN Equity | UE1: UHS UN Equity | UF1: ULTA UW Equity | UG1: UNH UN Equity | UH1: UBER UN Equity | UI1: UNM UN Equity | UJ1: UNP UN Equity | UK1: UPS UN Equity | UL1: URI UN Equity | UM1: USB UN Equity | UN1: V UN Equity | UO1: VAR UN Equity | UP1: VFC UN Equity | UQ1: VLO UN Equity | UR1: VMC UN Equity | US1: VICI UN Equity | UT1: VNO UN Equity | UU1: VNT UN Equity | UV1: VLTO UN Equity | UW1: VRSK UW Equity | UX1: VRSN UW Equity | UY1: VRTX UW Equity | UZ1: VTR UN Equity | VA1: VTRS UW Equity | VB1: VST UN Equity | VC1: VZ UN Equity | VD1: WAB UN Equity | VE1: WAT UN Equity | VF1: WBA UW Equity | VG1: WDC UW Equity | VH1: WBD UW Equity | VI1: WEC UN Equity | VJ1: WELL UN Equity | VK1: WDAY UW Equity | VL1: WFC UN Equity | VM1: WHR UN Equity | VN1: WM UN Equity | VO1: WMB UN Equity | VP1: WMT UN Equity | VQ1: WRB UN Equity | VR1: WRK UN Equity | VS1: WMT UW Equity | VT1: WST UN Equity | VU1: WTW UW Equity | VV1: WSM UN Equity | VW1: WU UN Equity | VX1: WY UN Equity | VY1: WYNN UW Equity | VZ1: XEL UW Equity | WA1: XLNX UW Equity | WB1: XOM UN Equity | WC1: XRAY UW Equity | WD1: XYL UN Equity | WE1: XRX UN Equity | WF1: YUM UN Equity | WG1: XYZ UN Equity | WH1: ZBH UN Equity | WI1: ZBRA UW Equity | WJ1: ZION UW Equity | WK1: ZTS UN Equity | WL1: 0848680D UN Equity | WM1: 1284849D UN Equity | WN1: 1436513D UN Equity | WO1: 1518855D US Equity | WP1: 1831877D UN Equity | WQ1: 1927294D UN Equity | WR1: 2078185D UN Equity | WS1: 0867887D UN Equity | WT1: 1255459D UW Equity | WU1: 1288453D UW Equity | WV1: 1500785D UN Equity | WW1: 1697067D UN Equity | WX1: 1856613D UN Equity | WY1: 0961514D UN Equity | WZ1: 1431816D UW Equity | XA1: 1715651D UN Equity | XB1: 1922150D UN Equity | XC1: 2370058D UN Equity | XD1: 1086832D UN Equity | XE1: 1448062D UW Equity | XF1: 1539941D UN Equity | XG1: 1806854D UN Equity | XH1: 2499073D UW Equity | XI1: 1566019D UN Equity | XJ1: 2616271D UN Equity | XK1: 1280712D UW Equity | XL1: 2326248D UW Equity | XM1: 1431816D UN Equity | XN1: 1541931D UW Equity | XO1: 1684442D UN Equity | XP1: 2558202D UW Equity | XQ1: 1683997D UW Equity | XR1: 1752754D UN Equity | XS1: 2258717D UN Equity | XT1: 2619871D UW Equity | XU1: 2544554D UW Equity | XV1: 1858968D UN Equity | XW1: 2557974D UN Equity | XX1: 2596482D UN Equity | XY1: AEP UN Equity | XZ1: 2071296D UN Equity | YA1: 2558202D UN Equity | YB1: 2584271D UN Equity | YC1: AGN UN Equity | YD1: 1996074D UN Equity | YE1: 2596516D UN Equity | YF1: AIV UN Equity | YG1: AA UN Equity | YH1: 9876549D UN Equity | YI1: AET UN Equity | YJ1: 9876566D UN Equity | YK1: 9876544D UN Equity | YL1: AMG UN Equity | YM1: AMD UR Equity | YN1: APA UN Equity | YO1: ADI UN Equity | YP1: ANDV UN Equity | YQ1: AN UN Equity | YR1: AYI UN Equity | YS1: ARG UN Equity | YT1: AMD UN Equity | YU1: BFH UN Equity | YV1: BBBYQ UW Equity | YW1: BHF UW Equity | YX1: ANF UN Equity | YY1: ATI UN Equity | YZ1: ANRZQ UN Equity | ZA1: BCR UN Equity | ZB1: AVP UN Equity | ZC1: APOL UW Equity | ZD1: BHI UN Equity | ZE1: CBOE UW Equity | ZF1: BXLT UN Equity | ZG1: CELG UW Equity | ZH1: BRCM UW Equity | ZI1: BMS UN Equity | ZJ1: BIGGQ UN Equity | ZK1: BMC UW Equity | ZL1: CCEP UN Equity | ZM1: CHKAQ UN Equity | ZN1: BTUUQ UN Equity | ZO1: COTY UN Equity | ZP1: CBE UN Equity | ZQ1: COL UN Equity | ZR1: CPRI UN Equity | ZS1: CFN UN Equity | ZT1: CLF UN Equity | ZU1: CNX UN Equity | ZV1: CSRA UN Equity | ZW1: CPGX UN Equity | ZX1: CXO UN Equity | ZY1: CSX UN Equity | ZZ1: CVC UN Equity | AAA1: COV UN Equity | AAB1: CPPRQ UN Equity | AAC1: CVH UN Equity | AAD1: DOFSQ UN Equity | AAE1: DNRCQ UN Equity | AAF1: CVSA UN Equity | AAG1: DFODQ UN Equity | AAH1: ETFC UW Equity | AAI1: ENDPQ UW Equity | AAJ1: ESRX UW Equity | AAK1: EVHC UN Equity | AAL1: EXC UN Equity | AAM1: FDO UN Equity | AAN1: FL UN Equity | AAO1: FLR UN Equity | AAP1: FTI UN Equity | AAQ1: FTRCQ UW Equity | AAR1: FOSL UW Equity | AAS1: FHN UN Equity | AAT1: GAS UN Equity | AAU1: GGP UN Equity | AAV1: FHI UN Equity | AAW1: GME UN Equity | AAX1: GHC UN Equity | AAY1: GMCR UW Equity | AAZ1: GT UW Equity | ABA1: GNW UN Equity | ABB1: HAR UN Equity | ABC1: HOG UN Equity | ABD1: HP UN Equity | ABE1: HCBK UW Equity | ABF1: HRB UN Equity | ABG1: GR UN Equity | ABH1: HOT UN Equity | ABI1: GT UN Equity | ABJ1: HST UN Equity | ABK1: HNZ UN Equity | ABL1: HSP UN Equity | ABM1: HSH UN Equity | ABN1: JEF UN Equity | ABO1: JWN UN Equity | ABP1: JOY UN Equity | ABQ1: KDP UN Equity | ABR1: KSS UN Equity | ABS1: KRFT UW Equity | ABT1: LLTC UW Equity | ABU1: LM UN Equity | ABV1: LNT UN Equity | ABW1: LO UN Equity | ABX1: LVLT UN Equity | ABY1: M UN Equity | ABZ1: MAC UN Equity | ACA1: MAT UW Equity | ACB1: LXK UN Equity | ACC1: MAR UN Equity | ACD1: MJN UN Equity | ACE1: MNKKQ UN Equity | ACF1: MDLZ UN Equity | ACG1: MHS UN Equity | ACH1: MOLX UW Equity | ACI1: MUR UN Equity | ACJ1: MYL UW Equity | ACK1: NAVI UW Equity | ACL1: NBL UN Equity | ACM1: MWV UN Equity | ACN1: NBR UN Equity | ACO1: NFX UN Equity | ACP1: NEBLQ UN Equity | ACQ1: NBL UW Equity | ACR1: NKTR UW Equity | ACS1: NWL UN Equity | ACT1: OI UN Equity | ACU1: PARA UN Equity | ACV1: ORCL UW Equity | ACW1: PBI UN Equity | ACX1: PDCO UW Equity | ACY1: PCP UN Equity | ACZ1: PEP UN Equity | ADA1: PFG UN Equity | ADB1: PETM UW Equity | ADC1: PRGO UW Equity | ADD1: R UN Equity | ADE1: RAI UN Equity | ADF1: QEP UN Equity | ADG1: REG UN Equity | ADH1: RDC UN Equity | ADI1: RHT UN Equity | ADJ1: RIG UN Equity | ADK1: RRC UN Equity | ADL1: RRD UW Equity | ADM1: RTN UN Equity | ADN1: SCG UN Equity | ADO1: SIG UN Equity | ADP1: SHLDQ UW Equity | ADQ1: SIAL UW Equity | ADR1: SLM UW Equity | ADS1: SRCL UW Equity | ADT1: STJ UN Equity | ADU1: SVU UN Equity | ADV1: SWN UN Equity | ADW1: SWY UN Equity | ADX1: TDC UN Equity | ADY1: TFCF UW Equity | ADZ1: TEG UN Equity | AEA1: TFCFA UW Equity | AEB1: TER UN Equity | AEC1: TGNA UN Equity | AED1: THC UN Equity | AEE1: TNL UN Equity | AEF1: TIE UN Equity | AEG1: TRIP UW Equity | AEH1: TMUS UN Equity | AEI1: TSS UN Equity | AEJ1: TWC UN Equity | AEK1: TWX UN Equity | AEL1: UAL UN Equity | AEM1: URBN UW Equity | AEN1: VALPQ UN Equity | AEO1: VIAB UW Equity | AEP1: VIAV UW Equity | AEQ1: WBA UN Equity | AER1: WDC UN Equity | AES1: WFM UW Equity | AET1: WCG UN Equity | AEU1: WINMQ UW Equity | AEV1: WPX UN Equity | AEW1: X UN Equity | AEX1: XEL UN Equity | AEY1: XEC UN Equity
A2: 40935
A3: 41026 | B3: =('AVG TARGET'!B3/PX_LAST!B3)*('AVG TARGET'!B2/PX_LAST!B2)-1 -> 0.25857541 | C3: =('AVG TARGET'!C3/PX_LAST!C3)*('AVG TARGET'!C2/PX_LAST!C2)-1 -> #VALUE! | D3: =('AVG TARGET'!D3/PX_LAST!D3)*('AVG TARGET'!D2/PX_LAST!D2)-1 -> #VALUE! | E3: =('AVG TARGET'!E3/PX_LAST!E3)*('AVG TARGET'!E2/PX_LAST!E2)-1 -> 0.36550609 | F3: =('AVG TARGET'!F3/PX_LAST!F3)*('AVG TARGET'!F2/PX_LAST!F2)-1 -> #VALUE! | G3: =('AVG TARGET'!G3/PX_LAST!G3)*('AVG TARGET'!G2/PX_LAST!G2)-1 -> 0.56407249 | H3: =('AVG TARGET'!H3/PX_LAST!H3)*('AVG TARGET'!H2/PX_LAST!H2)-1 -> #VALUE! | I3: =('AVG TARGET'!I3/PX_LAST!I3)*('AVG TARGET'!I2/PX_LAST!I2)-1 -> #VALUE! | ... AEY3: =('AVG TARGET'!AEY3/PX_LAST!AEY3)*('AVG TARGET'!AEY2/PX_LAST!AEY2)-1 -> 0.67612425
A4: 41117 | B4: =('AVG TARGET'!B4/PX_LAST!B4)*('AVG TARGET'!B3/PX_LAST!B3)-1 -> 0.2564639 | C4: =('AVG TARGET'!C4/PX_LAST!C4)*('AVG TARGET'!C3/PX_LAST!C3)-1 -> #VALUE! | D4: =('AVG TARGET'!D4/PX_LAST!D4)*('AVG TARGET'!D3/PX_LAST!D3)-1 -> #VALUE! | E4: =('AVG TARGET'!E4/PX_LAST!E4)*('AVG TARGET'!E3/PX_LAST!E3)-1 -> 0.64517119 | F4: =('AVG TARGET'!F4/PX_LAST!F4)*('AVG TARGET'!F3/PX_LAST!F3)-1 -> #VALUE! | G4: =('AVG TARGET'!G4/PX_LAST!G4)*('AVG TARGET'!G3/PX_LAST!G3)-1 -> 0.55165059 | H4: =('AVG TARGET'!H4/PX_LAST!H4)*('AVG TARGET'!H3/PX_LAST!H3)-1 -> #VALUE! | I4: =('AVG TARGET'!I4/PX_LAST!I4)*('AVG TARGET'!I3/PX_LAST!I3)-1 -> #VALUE! | ... AEY4: =('AVG TARGET'!AEY4/PX_LAST!AEY4)*('AVG TARGET'!AEY3/PX_LAST!AEY3)-1 -> 0.5585828
A5: 41207 | B5: =('AVG TARGET'!B5/PX_LAST!B5)*('AVG TARGET'!B4/PX_LAST!B4)-1 -> 0.2704241 | C5: =('AVG TARGET'!C5/PX_LAST!C5)*('AVG TARGET'!C4/PX_LAST!C4)-1 -> #VALUE! | D5: =('AVG TARGET'!D5/PX_LAST!D5)*('AVG TARGET'!D4/PX_LAST!D4)-1 -> #VALUE! | E5: =('AVG TARGET'!E5/PX_LAST!E5)*('AVG TARGET'!E4/PX_LAST!E4)-1 -> 0.78272401 | F5: =('AVG TARGET'!F5/PX_LAST!F5)*('AVG TARGET'!F4/PX_LAST!F4)-1 -> #VALUE! | G5: =('AVG TARGET'!G5/PX_LAST!G5)*('AVG TARGET'!G4/PX_LAST!G4)-1 -> 0.60705621 | H5: =('AVG TARGET'!H5/PX_LAST!H5)*('AVG TARGET'!H4/PX_LAST!H4)-1 -> #VALUE! | I5: =('AVG TARGET'!I5/PX_LAST!I5)*('AVG TARGET'!I4/PX_LAST!I4)-1 -> #VALUE! | ... AEY5: =('AVG TARGET'!AEY5/PX_LAST!AEY5)*('AVG TARGET'!AEY4/PX_LAST!AEY4)-1 -> 0.65545524
A6: 41298 | B6: =('AVG TARGET'!B6/PX_LAST!B6)*('AVG TARGET'!B5/PX_LAST!B5)-1 -> 0.23000151 | C6: =('AVG TARGET'!C6/PX_LAST!C6)*('AVG TARGET'!C5/PX_LAST!C5)-1 -> #VALUE! | D6: =('AVG TARGET'!D6/PX_LAST!D6)*('AVG TARGET'!D5/PX_LAST!D5)-1 -> #VALUE! | E6: =('AVG TARGET'!E6/PX_LAST!E6)*('AVG TARGET'!E5/PX_LAST!E5)-1 -> 0.3897645 | F6: =('AVG TARGET'!F6/PX_LAST!F6)*('AVG TARGET'!F5/PX_LAST!F5)-1 -> #VALUE! | G6: =('AVG TARGET'!G6/PX_LAST!G6)*('AVG TARGET'!G5/PX_LAST!G5)-1 -> 0.77906802 | H6: =('AVG TARGET'!H6/PX_LAST!H6)*('AVG TARGET'!H5/PX_LAST!H5)-1 -> #VALUE! | I6: =('AVG TARGET'!I6/PX_LAST!I6)*('AVG TARGET'!I5/PX_LAST!I5)-1 -> #VALUE! | ... AEY6: =('AVG TARGET'!AEY6/PX_LAST!AEY6)*('AVG TARGET'!AEY5/PX_LAST!AEY5)-1 -> 0.56373624
A7: 41388 | B7: =('AVG TARGET'!B7/PX_LAST!B7)*('AVG TARGET'!B6/PX_LAST!B6)-1 -> 0.17975495 | C7: =('AVG TARGET'!C7/PX_LAST!C7)*('AVG TARGET'!C6/PX_LAST!C6)-1 -> #VALUE! | D7: =('AVG TARGET'!D7/PX_LAST!D7)*('AVG TARGET'!D6/PX_LAST!D6)-1 -> #VALUE! | E7: =('AVG TARGET'!E7/PX_LAST!E7)*('AVG TARGET'!E6/PX_LAST!E6)-1 -> 0.17855302 | F7: =('AVG TARGET'!F7/PX_LAST!F7)*('AVG TARGET'!F6/PX_LAST!F6)-1 -> #VALUE! | G7: =('AVG TARGET'!G7/PX_LAST!G7)*('AVG TARGET'!G6/PX_LAST!G6)-1 -> 0.8736216 | H7: =('AVG TARGET'!H7/PX_LAST!H7)*('AVG TARGET'!H6/PX_LAST!H6)-1 -> #VALUE! | I7: =('AVG TARGET'!I7/PX_LAST!I7)*('AVG TARGET'!I6/PX_LAST!I6)-1 -> 0.0086748669 | ... AEY7: =('AVG TARGET'!AEY7/PX_LAST!AEY7)*('AVG TARGET'!AEY6/PX_LAST!AEY6)-1 -> 0.38282503
A8: 41478 | B8: =('AVG TARGET'!B8/PX_LAST!B8)*('AVG TARGET'!B7/PX_LAST!B7)-1 -> 0.15845359 | C8: =('AVG TARGET'!C8/PX_LAST!C8)*('AVG TARGET'!C7/PX_LAST!C7)-1 -> #VALUE! | D8: =('AVG TARGET'!D8/PX_LAST!D8)*('AVG TARGET'!D7/PX_LAST!D7)-1 -> #VALUE! | E8: =('AVG TARGET'!E8/PX_LAST!E8)*('AVG TARGET'!E7/PX_LAST!E7)-1 -> 0.15762287 | F8: =('AVG TARGET'!F8/PX_LAST!F8)*('AVG TARGET'!F7/PX_LAST!F7)-1 -> #VALUE! | G8: =('AVG TARGET'!G8/PX_LAST!G8)*('AVG TARGET'!G7/PX_LAST!G7)-1 -> 0.68378341 | H8: =('AVG TARGET'!H8/PX_LAST!H8)*('AVG TARGET'!H7/PX_LAST!H7)-1 -> #VALUE! | I8: =('AVG TARGET'!I8/PX_LAST!I8)*('AVG TARGET'!I7/PX_LAST!I7)-1 -> 0.077188851 | ... AEY8: =('AVG TARGET'!AEY8/PX_LAST!AEY8)*('AVG TARGET'!AEY7/PX_LAST!AEY7)-1 -> 0.25851424
A9: 41568 | B9: =('AVG TARGET'!B9/PX_LAST!B9)*('AVG TARGET'!B8/PX_LAST!B8)-1 -> 0.14203877 | C9: =('AVG TARGET'!C9/PX_LAST!C9)*('AVG TARGET'!C8/PX_LAST!C8)-1 -> #VALUE! | D9: =('AVG TARGET'!D9/PX_LAST!D9)*('AVG TARGET'!D8/PX_LAST!D8)-1 -> #VALUE! | E9: =('AVG TARGET'!E9/PX_LAST!E9)*('AVG TARGET'!E8/PX_LAST!E8)-1 -> 0.15534068 | F9: =('AVG TARGET'!F9/PX_LAST!F9)*('AVG TARGET'!F8/PX_LAST!F8)-1 -> #VALUE! | G9: =('AVG TARGET'!G9/PX_LAST!G9)*('AVG TARGET'!G8/PX_LAST!G8)-1 -> 0.33103509 | H9: =('AVG TARGET'!H9/PX_LAST!H9)*('AVG TARGET'!H8/PX_LAST!H8)-1 -> #VALUE! | I9: =('AVG TARGET'!I9/PX_LAST!I9)*('AVG TARGET'!I8/PX_LAST!I8)-1 -> 0.13060726 | ... AEY9: =('AVG TARGET'!AEY9/PX_LAST!AEY9)*('AVG TARGET'!AEY8/PX_LAST!AEY8)-1 -> 0.049069607
A10: 41660 | B10: =('AVG TARGET'!B10/PX_LAST!B10)*('AVG TARGET'!B9/PX_LAST!B9)-1 -> 0.15230449 | C10: =('AVG TARGET'!C10/PX_LAST!C10)*('AVG TARGET'!C9/PX_LAST!C9)-1 -> #VALUE! | D10: =('AVG TARGET'!D10/PX_LAST!D10)*('AVG TARGET'!D9/PX_LAST!D9)-1 -> #VALUE! | E10: =('AVG TARGET'!E10/PX_LAST!E10)*('AVG TARGET'!E9/PX_LAST!E9)-1 -> 0.14580864 | F10: =('AVG TARGET'!F10/PX_LAST!F10)*('AVG TARGET'!F9/PX_LAST!F9)-1 -> #VALUE! | G10: =('AVG TARGET'!G10/PX_LAST!G10)*('AVG TARGET'!G9/PX_LAST!G9)-1 -> 0.16704793 | H10: =('AVG TARGET'!H10/PX_LAST!H10)*('AVG TARGET'!H9/PX_LAST!H9)-1 -> #VALUE! | I10: =('AVG TARGET'!I10/PX_LAST!I10)*('AVG TARGET'!I9/PX_LAST!I9)-1 -> 0.18831437 | ... AEY10: =('AVG TARGET'!AEY10/PX_LAST!AEY10)*('AVG TARGET'!AEY9/PX_LAST!AEY9)-1 -> 0.06597681
A11: 41750 | B11: =('AVG TARGET'!B11/PX_LAST!B11)*('AVG TARGET'!B10/PX_LAST!B10)-1 -> 0.1771984 | C11: =('AVG TARGET'!C11/PX_LAST!C11)*('AVG TARGET'!C10/PX_LAST!C10)-1 -> #VALUE! | D11: =('AVG TARGET'!D11/PX_LAST!D11)*('AVG TARGET'!D10/PX_LAST!D10)-1 -> #VALUE! | E11: =('AVG TARGET'!E11/PX_LAST!E11)*('AVG TARGET'!E10/PX_LAST!E10)-1 -> 0.21131135 | F11: =('AVG TARGET'!F11/PX_LAST!F11)*('AVG TARGET'!F10/PX_LAST!F10)-1 -> #VALUE! | G11: =('AVG TARGET'!G11/PX_LAST!G11)*('AVG TARGET'!G10/PX_LAST!G10)-1 -> 0.24515455 | H11: =('AVG TARGET'!H11/PX_LAST!H11)*('AVG TARGET'!H10/PX_LAST!H10)-1 -> #VALUE! | I11: =('AVG TARGET'!I11/PX_LAST!I11)*('AVG TARGET'!I10/PX_LAST!I10)-1 -> 0.27626118 | ... AEY11: =('AVG TARGET'!AEY11/PX_LAST!AEY11)*('AVG TARGET'!AEY10/PX_LAST!AEY10)-1 -> 0.20630135
A12: 41838 | B12: =('AVG TARGET'!B12/PX_LAST!B12)*('AVG TARGET'!B11/PX_LAST!B11)-1 -> 0.18265842 | C12: =('AVG TARGET'!C12/PX_LAST!C12)*('AVG TARGET'!C11/PX_LAST!C11)-1 -> #VALUE! | D12: =('AVG TARGET'!D12/PX_LAST!D12)*('AVG TARGET'!D11/PX_LAST!D11)-1 -> #VALUE! | E12: =('AVG TARGET'!E12/PX_LAST!E12)*('AVG TARGET'!E11/PX_LAST!E11)-1 -> 0.32523135 | F12: =('AVG TARGET'!F12/PX_LAST!F12)*('AVG TARGET'!F11/PX_LAST!F11)-1 -> #VALUE! | G12: =('AVG TARGET'!G12/PX_LAST!G12)*('AVG TARGET'!G11/PX_LAST!G11)-1 -> 0.21289242 | H12: =('AVG TARGET'!H12/PX_LAST!H12)*('AVG TARGET'!H11/PX_LAST!H11)-1 -> #VALUE! | I12: =('AVG TARGET'!I12/PX_LAST!I12)*('AVG TARGET'!I11/PX_LAST!I11)-1 -> 0.30350523 | ... AEY12: =('AVG TARGET'!AEY12/PX_LAST!AEY12)*('AVG TARGET'!AEY11/PX_LAST!AEY11)-1 -> 0.22153153
